<?xml version="1.0"?>
<robot xmlns:xacro="http://www.ros.org/wiki/xacro" >

    <xacro:include filename="inertial_macros.xacro"/>
    <xacro:include filename="materials.xacro"/>

    <!-- BASE LINK -->

    <link name="base_link">

    </link>
    
    <!-- BASE_FOOTPRINT LINK -->

    <joint name="base_footprint_joint" type="fixed">
        <parent link="base_link"/>
        <child link="base_footprint"/>
        <origin xyz="0 0 0" rpy="0 0 0"/>
    </joint>

    <link name="base_footprint">
    </link>


    <!-- CHASSIS LINK -->

    <joint name="chassis_joint" type="fixed">
        <parent link="base_link"/>
        <child link="chassis"/>
        <origin xyz="-0.135 0 0"/>
    </joint>

    <link name="chassis">
        <visual>
            <origin xyz="0.135 0 0.04"/>
            <geometry>
                <box size="0.27 0.16 0.08"/>
            </geometry>
            <material name="white"/>
        </visual>
        <collision>
            <origin xyz="0.135 0 0.04"/>
            <geometry>
                <box size="0.27 0.16 0.08"/>
            </geometry>
        </collision>
        <xacro:inertial_box mass="0.5" x="0.27" y="0.16" z="0.08"> 
            <origin xyz="0.135 0 0.04" rpy="0 0 0" />
        </xacro:inertial_box>
    </link>

    <gazebo reference="chassis">
        <material>Gazebo/White</material>
    </gazebo>
    
    <!-- REAR LEFT WHEEL LINK -->

    <joint name="rear_left_wheel_joint" type="continuous">
        <parent link="base_link"/>
        <child link="rear_left_wheel"/>
        <origin xyz="-0.090 0.09675 -0.0375" rpy="-${pi/2} 0 0" />
        <axis xyz="0 0 1"/>
    </joint>

    <link name="rear_left_wheel">
        <visual>
            <geometry>
                <cylinder radius="0.0375" length="0.0325"/>
            </geometry>
            <material name="black"/>
        </visual>
        <collision>
            <geometry>
                <cylinder radius="0.0375" length="0.0325"/>
            </geometry>
        </collision>
        <xacro:inertial_cylinder mass="0.1" length="0.0325" radius="0.0375">
            <origin xyz="0 0 0" rpy="0 0 0"/>
        </xacro:inertial_cylinder>
    </link>

    <gazebo reference="rear_left_wheel">
        <material>Gazebo/Black</material>
    </gazebo>

    <!-- REAR RIGHT WHEEL LINK -->

    <joint name="rear_right_wheel_joint" type="continuous">
        <parent link="base_link"/>
        <child link="rear_right_wheel"/>
        <origin xyz="-0.090 -0.09675 -0.0375" rpy="${pi/2} 0 0" />
        <axis xyz="0 0 -1"/>
    </joint>

    <link name="rear_right_wheel">
        <visual>
            <geometry>
                <cylinder radius="0.0375" length="0.0325"/>
            </geometry>
            <material name="black"/>
        </visual>
        <collision>
            <geometry>
                <cylinder radius="0.0375" length="0.0325"/>
            </geometry>
        </collision>
        <xacro:inertial_cylinder mass="0.1" length="0.0325" radius="0.0375">
            <origin xyz="0 0 0" rpy="0 0 0"/>
        </xacro:inertial_cylinder>
    </link>

    <gazebo reference="rear_right_wheel">
        <material>Gazebo/Black</material>
    </gazebo>

       <!-- FRONT LEFT WHEEL LINK -->

    <joint name="front_left_wheel_joint" type="continuous">
        <parent link="base_link"/>
        <child link="front_left_wheel"/>
        <origin xyz="0.080 0.09675 -0.0375" rpy="-${pi/2} 0 0" />
        <axis xyz="0 0 1"/>
    </joint>

    <link name="front_left_wheel">
        <visual>
            <geometry>
                <cylinder radius="0.0375" length="0.0325"/>
            </geometry>
            <material name="black"/>
        </visual>
        <collision>
            <geometry>
                <cylinder radius="0.0375" length="0.0325"/>
            </geometry>
        </collision>
        <xacro:inertial_cylinder mass="0.1" length="0.0325" radius="0.0375">
            <origin xyz="0 0 0" rpy="0 0 0"/>
        </xacro:inertial_cylinder>
    </link>

    <gazebo reference="front_left_wheel">
        <material>Gazebo/Black</material>
    </gazebo>

    <!-- FRONT RIGHT WHEEL LINK -->

    <joint name="front_right_wheel_joint" type="continuous">
        <parent link="base_link"/>
        <child link="front_right_wheel"/>
        <origin xyz="0.080 -0.09675 -0.0375" rpy="${pi/2} 0 0" />
        <axis xyz="0 0 -1"/>
    </joint>

    <link name="front_right_wheel">
        <visual>
            <geometry>
                <cylinder radius="0.0375" length="0.0325"/>
            </geometry>
            <material name="black"/>
        </visual>
        <collision>
            <geometry>
                <cylinder radius="0.0375" length="0.0325"/>
            </geometry>
        </collision>
        <xacro:inertial_cylinder mass="0.1" length="0.0325" radius="0.0375">
            <origin xyz="0 0 0" rpy="0 0 0"/>
        </xacro:inertial_cylinder>
    </link>    

    <gazebo reference="front_right_wheel">
        <material>Gazebo/Black</material>
    </gazebo>
   
</robot>
